Workbook

Sheet Leeswijzer
A1: Financieel Vastgoedkompas · relationeel datamodel
A2: CONCEPT v0.1 · 2 oktober 2026 · KplusV · nog niet vastgesteld door het kernteam
A4: LET OP: dummy-data | B4: Deze werkmap is gevuld met DUMMY-gegevens als onderlegger voor een website-prototype. Wat hier staat is niet gecontroleerd en niet vastgesteld, en mag niet als inhoud van het Kompas worden gepubliceerd. Elk record dat is toegevoegd heeft in notes_internal de tekst DUMMY. Bij bestaande records staat 'DUMMY-aanvulling' met de velden die zijn aangevuld. Tabblad Dummy_overzicht telt per tabel.
A5: Wat is echt | B5: De 77 instrumenten (naam, omschrijving, bron, beheerder, eigenaartype, status) komen uit catalogus v0.1 van KplusV. Idem de hiaten- en dekkingsanalyse. De waardelijsten komen uit de modelbeschrijving. Alle koppelingen, classificaties en tekst die daarbovenop zijn gezet zijn dummy: rollen, fasen en beslismomenten per instrument, openstelling, voorwaarden, relaties, kennisproducten, validatie, feedback.
A6: Wat is verzonnen | B6: Alle beslismomenten, informatiebehoeften, handelingsperspectieven, knelpunten, informatieoverdracht, functietitels en kennisproducten. Idem alle datums van openstelling, controles en wijzigingen, en alle URL's naar example.org. Bedragen bij effecten zijn bewust leeg gelaten.
A7: Tabbladen vooraan | B7: Tabellen: overzicht van alle 65 tabellen met aantal records. Dummy_overzicht: per tabel hoeveel records echt zijn en hoeveel dummy. Velden: datadictionary met vulgraad. Keuzelijsten: toegestane waarden. Afwijkingen: gaten in de originele modelbeschrijving (de tabel beslismoment is hier met dummy gevuld, de gaten zelf zijn niet opgelost).
A8: Tabeltabbladen | B8: Rij 1 bevat de veldnamen precies zoals in het model. Verwijzingen (velden op _id) bevatten de leesbare code of naam van het doelrecord, bijvoorbeeld ROL-003 of I-001; entity_id bevat de UUID. Houd de muis op een kolomkop voor type, verplichting en toelichting.
A9: Voor de websitebouwer | B9: Naast deze werkmap staat dezelfde inhoud als JSON (kompas_dummy_data.json): per tabel een lijst records, met verwijzingen als leesbare sleutel. De hoofdroute voor navigatie: opgave > procesfase > beslismoment > rol, informatiebehoefte, financiële vraag, handelingsperspectief > instrument via instrument_beslismoment. Filters: rol, eigenaartype, objecttype, financiële vraag, financiële route, werkingsgebied, openstelling.
A10: Kleur kolomkop | B10: Donkerviolet = verplicht veld. Lichtviolet = optioneel veld. Grijs = standaard beheerveld.
A11: Datums en ja/nee | B11: Datums als jjjj-mm-dd. Booleans als ja of nee.
A12: Bron | B12: Modelbeschrijving 'Concreet datamodel Financieel Vastgoedkompas' en Financieel_Vastgoedkompas_instrumentendatabase_v0.1.xlsx (versie 4 september 2026).

Sheet Dummy_overzicht
A1: Dummy-overzicht
A2: Per tabel: aantal records, waarvan echt (uit catalogus v0.1 of waardelijst) en waarvan DUMMY. Dummy-records dragen DUMMY in notes_internal.
A4: Nr | B4: Tabel | C4: Domein | D4: Records | E4: Echt / voorstel | F4: DUMMY | G4: Aandeel DUMMY
A5: 1 | B5: opgave | C5: A. Navigatie | D5: 10 | E5: 0 | F5: 10 | G5: =IF(D5=0,0,F5/D5) -> 1
A6: 2 | B6: procesniveau | C6: A. Navigatie | D6: 4 | E6: 0 | F6: 4 | G6: =IF(D6=0,0,F6/D6) -> 1
A7: 3 | B7: procesfase | C7: A. Navigatie | D7: 12 | E7: 0 | F7: 12 | G7: =IF(D7=0,0,F7/D7) -> 1
A8: 4 | B8: procesfase_relatie | C8: A. Navigatie | D8: 16 | E8: 0 | F8: 16 | G8: =IF(D8=0,0,F8/D8) -> 1
A9: 5 | B9: beslismoment | C9: A. Navigatie | D9: 16 | E9: 0 | F9: 16 | G9: =IF(D9=0,0,F9/D9) -> 1
A10: 6 | B10: besluittype | C10: A. Navigatie | D10: 14 | E10: 14 | F10: 0 | G10: =IF(D10=0,0,F10/D10) -> 0
A11: 7 | B11: rol | C11: A. Navigatie | D11: 22 | E11: 0 | F11: 22 | G11: =IF(D11=0,0,F11/D11) -> 1
A12: 8 | B12: rolcluster | C12: A. Navigatie | D12: 9 | E12: 9 | F12: 0 | G12: =IF(D12=0,0,F12/D12) -> 0
A13: 9 | B13: functie_alias | C13: A. Navigatie | D13: 18 | E13: 0 | F13: 18 | G13: =IF(D13=0,0,F13/D13) -> 1
A14: 10 | B14: eigenaartype | C14: A. Navigatie | D14: 10 | E14: 10 | F14: 0 | G14: =IF(D14=0,0,F14/D14) -> 0
A15: 11 | B15: objecttype | C15: A. Navigatie | D15: 21 | E15: 21 | F15: 0 | G15: =IF(D15=0,0,F15/D15) -> 0
A16: 12 | B16: financiele_vraag | C16: B. Besluitondersteuning | D16: 12 | E16: 0 | F16: 12 | G16: =IF(D16=0,0,F16/D16) -> 1
... A69: 65 | B69: gebruikersfeedback | C69: D. Beheer en validatie | D69: 8 | E69: 0 | F69: 8 | G69: =IF(D69=0,0,F69/D69) -> 1
B70: Totaal | D70: =SUM(D5:D69) -> 2325 | E70: =SUM(E5:E69) -> 278 | F70: =SUM(F5:F69) -> 2047

Sheet Tabellen
A1: Overzicht tabellen
A2: Aantal records telt automatisch mee. Fase volgt §18 van de modelbeschrijving; 'niet ingedeeld' = daar niet genoemd.
A4: Nr | B4: Tabel (tabblad) | C4: Sectie | D4: Domein | E4: Soort | F4: Fase §18 | G4: Velden | H4: Verplichte velden | I4: Records | J4: Omschrijving
A5: 1 | B5: opgave | C5: 4.1 | D5: A. Navigatie | E5: entiteit | F5: 2 | G5: 20 | H5: 12 | I5: =COUNTA(opgave!$A$2:$A$2000) -> 10 | J5: Situatie, aanleiding of doel waarmee een gebruiker het Kompas binnenkomt.
A6: 2 | B6: procesniveau | C6: 4.2 | D6: A. Navigatie | E6: keuzelijsttabel | F6: 1 | G6: 14 | H6: 11 | I6: =COUNTA(procesniveau!$A$2:$A$2000) -> 4 | J6: Niveau waarop een proces speelt: portefeuille, programma, object of project.
A7: 3 | B7: procesfase | C7: 4.3 | D7: A. Navigatie | E7: entiteit | F7: 1 | G7: 21 | H7: 14 | I7: =COUNTA(procesfase!$A$2:$A$2000) -> 12 | J7: Fase binnen een procesniveau (voorstel: P1-P5 en O1-O7).
A8: 4 | B8: procesfase_relatie | C8: 4.4 | D8: A. Navigatie | E8: koppeltabel | F8: niet ingedeeld | G8: 16 | H8: 11 | I8: =COUNTA(procesfase_relatie!$A$2:$A$2000) -> 16 | J8: Verbindt fases aan elkaar zonder één lineair pad af te dwingen.
A9: 5 | B9: beslismoment | C9: 4.5 | D9: A. Navigatie | E9: entiteit | F9: 1 | G9: 27 | H9: 18 | I9: =COUNTA(beslismoment!$A$2:$A$2000) -> 16 | J9: Centrale navigatie-entiteit: het moment waarop een besluit wordt voorbereid of genomen.
A10: 6 | B10: besluittype | C10: 4.6 | D10: A. Navigatie | E10: keuzelijsttabel | F10: niet ingedeeld | G10: 14 | H10: 10 | I10: =COUNTA(besluittype!$A$2:$A$2000) -> 14 | J10: Type besluit.
A11: 7 | B11: rol | C11: 4.7 | D11: A. Navigatie | E11: entiteit | F11: 1 | G11: 21 | H11: 16 | I11: =COUNTA(rol!$A$2:$A$2000) -> 22 | J11: Generieke rol, los van lokale functietitels.
A12: 8 | B12: rolcluster | C12: 4.8 | D12: A. Navigatie | E12: keuzelijsttabel | F12: niet ingedeeld | G12: 14 | H12: 10 | I12: =COUNTA(rolcluster!$A$2:$A$2000) -> 9 | J12: Cluster van rollen.
A13: 9 | B13: functie_alias | C13: 4.9 | D13: A. Navigatie | E13: entiteit | F13: niet ingedeeld | G13: 15 | H13: 10 | I13: =COUNTA(functie_alias!$A$2:$A$2000) -> 18 | J13: Koppelt gemeentelijke functietitels aan generieke rollen.
A14: 10 | B14: eigenaartype | C14: 4.10 | D14: A. Navigatie | E14: keuzelijsttabel | F14: 1 | G14: 15 | H14: 11 | I14: =COUNTA(eigenaartype!$A$2:$A$2000) -> 10 | J14: Type vastgoedeigenaar.
A15: 11 | B15: objecttype | C15: 4.11 | D15: A. Navigatie | E15: keuzelijsttabel | F15: 1 | G15: 15 | H15: 10 | I15: =COUNTA(objecttype!$A$2:$A$2000) -> 21 | J15: Hiërarchische indeling van vastgoedobjecten.
A16: 12 | B16: financiele_vraag | C16: 5.1 | D16: B. Besluitondersteuning | E16: entiteit | F16: 1 | G16: 17 | H16: 12 | I16: =COUNTA(financiele_vraag!$A$2:$A$2000) -> 12 | J16: Financiële vraag die op een beslismoment speelt.
A17: 13 | B17: financieel_thema | C17: 5.2 | D17: B. Besluitondersteuning | E17: keuzelijsttabel | F17: 1 | G17: 15 | H17: 10 | I17: =COUNTA(financieel_thema!$A$2:$A$2000) -> 19 | J17: Financieel thema, hiërarchisch.
A18: 14 | B18: informatiebehoefte | C18: 5.3 | D18: B. Besluitondersteuning | E18: entiteit | F18: 2 | G18: 21 | H18: 13 | I18: =COUNTA(informatiebehoefte!$A$2:$A$2000) -> 15 | J18: Informatie die een rol op een beslismoment nodig heeft.
A19: 15 | B19: informatietype | C19: 5.4 | D19: B. Besluitondersteuning | E19: keuzelijsttabel | F19: niet ingedeeld | G19: 14 | H19: 10 | I19: =COUNTA(informatietype!$A$2:$A$2000) -> 18 | J19: Type informatie.
A20: 16 | B20: beslisproduct | C20: 5.5 | D20: B. Besluitondersteuning | E20: entiteit | F20: 2 | G20: 16 | H20: 11 | I20: =COUNTA(beslisproduct!$A$2:$A$2000) -> 15 | J20: Output waarmee een beslissing wordt voorbereid of onderbouwd.
A21: 17 | B21: handelingsperspectief | C21: 5.6 | D21: B. Besluitondersteuning | E21: entiteit | F21: 2 | G21: 18 | H21: 12 | I21: =COUNTA(handelingsperspectief!$A$2:$A$2000) -> 10 | J21: Concrete aanbevolen actie ('handelen boven informeren').
A22: 18 | B22: knelpunt | C22: 5.7 | D22: B. Besluitondersteuning | E22: entiteit | F22: niet ingedeeld | G22: 18 | H22: 13 | I22: =COUNTA(knelpunt!$A$2:$A$2000) -> 8 | J22: Risico of knelpunt in besluitvorming of informatieoverdracht.
A23: 19 | B23: informatieoverdracht | C23: 5.8 | D23: B. Besluitondersteuning | E23: entiteit | F23: 2 | G23: 20 | H23: 12 | I23: =COUNTA(informatieoverdracht!$A$2:$A$2000) -> 11 | J23: Welke rol welke informatie aan welke andere rol moet leveren op een beslismoment.
A24: 20 | B24: instrument | C24: 6.1 | D24: C. Instrumentenbibliotheek | E24: entiteit | F24: 1 | G24: 32 | H24: 18 | I24: =COUNTA(instrument!$A$2:$A$2000) -> 77 | J24: Instrument uit de catalogus.
A25: 21 | B25: instrumenttype | C25: 6.2 | D25: C. Instrumentenbibliotheek | E25: keuzelijsttabel | F25: 1 | G25: 15 | H25: 11 | I25: =COUNTA(instrumenttype!$A$2:$A$2000) -> 30 | J25: Type instrument, gegroepeerd in hoofdgroepen.
A26: 22 | B26: digitale_vorm | C26: 6.3 | D26: C. Instrumentenbibliotheek | E26: keuzelijsttabel | F26: niet ingedeeld | G26: 13 | H26: 9 | I26: =COUNTA(digitale_vorm!$A$2:$A$2000) -> 14 | J26: Digitale verschijningsvorm van een instrument.
A27: 23 | B27: organisatie | C27: 6.4 | D27: C. Instrumentenbibliotheek | E27: entiteit | F27: 1 | G27: 18 | H27: 9 | I27: =COUNTA(organisatie!$A$2:$A$2000) -> 56 | J27: Organisatie (bronhouder, verstrekker, beheerder enzovoort).
A28: 24 | B28: organisatietype | C28: 6.5 | D28: C. Instrumentenbibliotheek | E28: keuzelijsttabel | F28: niet ingedeeld | G28: 14 | H28: 10 | I28: =COUNTA(organisatietype!$A$2:$A$2000) -> 15 | J28: Type organisatie.
A29: 25 | B29: instrument_organisatie | C29: 6.6 | D29: C. Instrumentenbibliotheek | E29: koppeltabel | F29: niet ingedeeld | G29: 16 | H29: 10 | I29: =COUNTA(instrument_organisatie!$A$2:$A$2000) -> 77 | J29: Rol van een organisatie bij een instrument.
A30: 26 | B30: bron | C30: 6.7 | D30: C. Instrumentenbibliotheek | E30: entiteit | F30: 1 | G30: 24 | H30: 13 | I30: =COUNTA(bron!$A$2:$A$2000) -> 76 | J30: Bron waarop inhoud is gebaseerd.
A31: 27 | B31: brontype | C31: 6.8 | D31: C. Instrumentenbibliotheek | E31: keuzelijsttabel | F31: niet ingedeeld | G31: 14 | H31: 10 | I31: =COUNTA(brontype!$A$2:$A$2000) -> 14 | J31: Type bron.
A32: 28 | B32: instrument_bron | C32: 6.9 | D32: C. Instrumentenbibliotheek | E32: koppeltabel | F32: 1 | G32: 15 | H32: 11 | I32: =COUNTA(instrument_bron!$A$2:$A$2000) -> 77 | J32: Bronnen per instrument.
A33: 29 | B33: instrument_rol | C33: 7.1 | D33: C. Instrumentenbibliotheek | E33: koppeltabel | F33: 1 | G33: 16 | H33: 11 | I33: =COUNTA(instrument_rol!$A$2:$A$2000) -> 183 | J33: Voor welke rollen een instrument relevant is.
A34: 30 | B34: instrument_procesfase | C34: 7.2 | D34: C. Instrumentenbibliotheek | E34: koppeltabel | F34: 1 | G34: 15 | H34: 11 | I34: =COUNTA(instrument_procesfase!$A$2:$A$2000) -> 79 | J34: In welke procesfasen een instrument bruikbaar is.
A35: 31 | B35: instrument_beslismoment | C35: 7.3 | D35: C. Instrumentenbibliotheek | E35: koppeltabel | F35: 1 | G35: 17 | H35: 13 | I35: =COUNTA(instrument_beslismoment!$A$2:$A$2000) -> 79 | J35: Belangrijkste koppeltabel van de bronnenlaag: welk instrument welk beslismoment ondersteunt.
A36: 32 | B36: instrument_opgave | C36: 7.4 | D36: C. Instrumentenbibliotheek | E36: koppeltabel | F36: niet ingedeeld | G36: 14 | H36: 10 | I36: =COUNTA(instrument_opgave!$A$2:$A$2000) -> 154 | J36: Instrumenten per opgave.
A37: 33 | B37: instrument_financiele_vraag | C37: 7.5 | D37: C. Instrumentenbibliotheek | E37: koppeltabel | F37: 1 | G37: 15 | H37: 10 | I37: =COUNTA(instrument_financiele_vraag!$A$2:$A$2000) -> 150 | J37: Welke financiële vragen een instrument beantwoordt.
A38: 34 | B38: instrument_eigenaartype | C38: 7.6 | D38: C. Instrumentenbibliotheek | E38: koppeltabel | F38: 1 | G38: 15 | H38: 11 | I38: =COUNTA(instrument_eigenaartype!$A$2:$A$2000) -> 121 | J38: Toepasbaarheid per eigenaartype.
A39: 35 | B39: instrument_objecttype | C39: 7.7 | D39: C. Instrumentenbibliotheek | E39: koppeltabel | F39: 1 | G39: 15 | H39: 11 | I39: =COUNTA(instrument_objecttype!$A$2:$A$2000) -> 95 | J39: Toepasbaarheid per objecttype.
A40: 36 | B40: financiele_route | C40: 8.1 | D40: C. Instrumentenbibliotheek | E40: entiteit | F40: niet ingedeeld | G40: 18 | H40: 12 | I40: =COUNTA(financiele_route!$A$2:$A$2000) -> 17 | J40: Financiële oplossingsrichting.
A41: 37 | B41: instrument_financiele_route | C41: 8.2 | D41: C. Instrumentenbibliotheek | E41: koppeltabel | F41: niet ingedeeld | G41: 16 | H41: 10 | I41: =COUNTA(instrument_financiele_route!$A$2:$A$2000) -> 77 | J41: Instrumenten per financiële route.
...

Sheet Velden
A1: Datadictionary
A2: Eén regel per veld. 'Gevuld' en 'Leeg, verplicht' tellen automatisch mee met de tabeltabbladen.
A4: Tabel | B4: Veld | C4: Type | D4: Verplicht | E4: Sleutel | F4: Verwijst naar | G4: Keuzelijst | H4: Toelichting | I4: Gevuld | J4: Leeg, verplicht
A5: opgave | B5: opgave_id | C5: UUID | D5: ja | E5: PK | H5: Primaire sleutel | I5: =COUNTA(opgave!A$2:A$2000) -> 10 | J5: =IF(D5="ja",COUNTA(opgave!$A$2:$A$2000)-I5,"") -> 0
A6: opgave | B6: opgave_code | C6: varchar(20) | D6: ja | H6: Unieke functionele code | I6: =COUNTA(opgave!B$2:B$2000) -> 10 | J6: =IF(D6="ja",COUNTA(opgave!$A$2:$A$2000)-I6,"") -> 0
A7: opgave | B7: naam | C7: varchar(200) | D7: ja | H7: Korte naam | I7: =COUNTA(opgave!C$2:C$2000) -> 10 | J7: =IF(D7="ja",COUNTA(opgave!$A$2:$A$2000)-I7,"") -> 0
A8: opgave | B8: korte_omschrijving | C8: varchar(500) | D8: ja | H8: Tekst voor navigatie | I8: =COUNTA(opgave!D$2:D$2000) -> 10 | J8: =IF(D8="ja",COUNTA(opgave!$A$2:$A$2000)-I8,"") -> 0
A9: opgave | B9: uitgebreide_omschrijving | C9: text | D9: nee | H9: Nadere inhoud | I9: =COUNTA(opgave!E$2:E$2000) -> 0 | J9: =IF(D9="ja",COUNTA(opgave!$A$2:$A$2000)-I9,"")
A10: opgave | B10: aanleiding | C10: text | D10: nee | H10: Trigger of probleem | I10: =COUNTA(opgave!F$2:F$2000) -> 0 | J10: =IF(D10="ja",COUNTA(opgave!$A$2:$A$2000)-I10,"")
A11: opgave | B11: gewenst_resultaat | C11: text | D11: nee | H11: Beoogde uitkomst | I11: =COUNTA(opgave!G$2:G$2000) -> 10 | J11: =IF(D11="ja",COUNTA(opgave!$A$2:$A$2000)-I11,"")
A12: opgave | B12: niveau_default | C12: varchar(30) | D12: nee | G12: portefeuille; programma; object; project | H12: Portefeuille, programma, object, project | I12: =COUNTA(opgave!H$2:H$2000) -> 10 | J12: =IF(D12="ja",COUNTA(opgave!$A$2:$A$2000)-I12,"")
A13: opgave | B13: primaire_doelgroep | C13: varchar(100) | D13: nee | H13: Samenvattend | I13: =COUNTA(opgave!I$2:I$2000) -> 0 | J13: =IF(D13="ja",COUNTA(opgave!$A$2:$A$2000)-I13,"")
A14: opgave | B14: sort_order | C14: integer | D14: ja | H14: Volgorde in interface | I14: =COUNTA(opgave!J$2:J$2000) -> 10 | J14: =IF(D14="ja",COUNTA(opgave!$A$2:$A$2000)-I14,"") -> 0
A15: opgave | B15: is_public | C15: boolean | D15: ja | G15: ja; nee | H15: Publiceerbaar | I15: =COUNTA(opgave!K$2:K$2000) -> 10 | J15: =IF(D15="ja",COUNTA(opgave!$A$2:$A$2000)-I15,"") -> 0
A16: opgave | B16: created_at | C16: datetime | D16: ja | H16: Datum en tijd van aanmaak | I16: =COUNTA(opgave!L$2:L$2000) -> 10 | J16: =IF(D16="ja",COUNTA(opgave!$A$2:$A$2000)-I16,"") -> 0
A17: opgave | B17: created_by | C17: varchar(255) | D17: ja | H17: Maker | I17: =COUNTA(opgave!M$2:M$2000) -> 10 | J17: =IF(D17="ja",COUNTA(opgave!$A$2:$A$2000)-I17,"") -> 0
A18: opgave | B18: updated_at | C18: datetime | D18: ja | H18: Laatste wijziging | I18: =COUNTA(opgave!N$2:N$2000) -> 10 | J18: =IF(D18="ja",COUNTA(opgave!$A$2:$A$2000)-I18,"") -> 0
A19: opgave | B19: updated_by | C19: varchar(255) | D19: ja | H19: Laatste bewerker | I19: =COUNTA(opgave!O$2:O$2000) -> 10 | J19: =IF(D19="ja",COUNTA(opgave!$A$2:$A$2000)-I19,"") -> 0
A20: opgave | B20: record_status | C20: varchar(30) | D20: ja | G20: actief; concept; gearchiveerd | H20: Actief, concept, gearchiveerd | I20: =COUNTA(opgave!P$2:P$2000) -> 10 | J20: =IF(D20="ja",COUNTA(opgave!$A$2:$A$2000)-I20,"") -> 0
A21: opgave | B21: version_number | C21: integer | D21: ja | H21: Versienummer van record | I21: =COUNTA(opgave!Q$2:Q$2000) -> 10 | J21: =IF(D21="ja",COUNTA(opgave!$A$2:$A$2000)-I21,"") -> 0
A22: opgave | B22: valid_from | C22: date | D22: nee | H22: Geldig vanaf | I22: =COUNTA(opgave!R$2:R$2000) -> 0 | J22: =IF(D22="ja",COUNTA(opgave!$A$2:$A$2000)-I22,"")
A23: opgave | B23: valid_until | C23: date | D23: nee | H23: Geldig tot | I23: =COUNTA(opgave!S$2:S$2000) -> 0 | J23: =IF(D23="ja",COUNTA(opgave!$A$2:$A$2000)-I23,"")
A24: opgave | B24: notes_internal | C24: text | D24: nee | H24: Interne beheerinformatie | I24: =COUNTA(opgave!T$2:T$2000) -> 10 | J24: =IF(D24="ja",COUNTA(opgave!$A$2:$A$2000)-I24,"")
A25: procesniveau | B25: procesniveau_id | C25: UUID | D25: ja | E25: PK | H25: Primaire sleutel | I25: =COUNTA(procesniveau!A$2:A$2000) -> 4 | J25: =IF(D25="ja",COUNTA(procesniveau!$A$2:$A$2000)-I25,"") -> 0
A26: procesniveau | B26: code | C26: varchar(10) | D26: ja | H26: PORT, PROG, OBJ, PROJ | I26: =COUNTA(procesniveau!B$2:B$2000) -> 4 | J26: =IF(D26="ja",COUNTA(procesniveau!$A$2:$A$2000)-I26,"") -> 0
A27: procesniveau | B27: naam | C27: varchar(100) | D27: ja | H27: Naam niveau | I27: =COUNTA(procesniveau!C$2:C$2000) -> 4 | J27: =IF(D27="ja",COUNTA(procesniveau!$A$2:$A$2000)-I27,"") -> 0
A28: procesniveau | B28: omschrijving | C28: text | D28: ja | H28: Afbakening | I28: =COUNTA(procesniveau!D$2:D$2000) -> 4 | J28: =IF(D28="ja",COUNTA(procesniveau!$A$2:$A$2000)-I28,"") -> 0
A29: procesniveau | B29: sort_order | C29: integer | D29: ja | H29: Volgorde | I29: =COUNTA(procesniveau!E$2:E$2000) -> 4 | J29: =IF(D29="ja",COUNTA(procesniveau!$A$2:$A$2000)-I29,"") -> 0
A30: procesniveau | B30: created_at | C30: datetime | D30: ja | H30: Datum en tijd van aanmaak | I30: =COUNTA(procesniveau!F$2:F$2000) -> 4 | J30: =IF(D30="ja",COUNTA(procesniveau!$A$2:$A$2000)-I30,"") -> 0
A31: procesniveau | B31: created_by | C31: varchar(255) | D31: ja | H31: Maker | I31: =COUNTA(procesniveau!G$2:G$2000) -> 4 | J31: =IF(D31="ja",COUNTA(procesniveau!$A$2:$A$2000)-I31,"") -> 0
A32: procesniveau | B32: updated_at | C32: datetime | D32: ja | H32: Laatste wijziging | I32: =COUNTA(procesniveau!H$2:H$2000) -> 4 | J32: =IF(D32="ja",COUNTA(procesniveau!$A$2:$A$2000)-I32,"") -> 0
A33: procesniveau | B33: updated_by | C33: varchar(255) | D33: ja | H33: Laatste bewerker | I33: =COUNTA(procesniveau!I$2:I$2000) -> 4 | J33: =IF(D33="ja",COUNTA(procesniveau!$A$2:$A$2000)-I33,"") -> 0
A34: procesniveau | B34: record_status | C34: varchar(30) | D34: ja | G34: actief; concept; gearchiveerd | H34: Actief, concept, gearchiveerd | I34: =COUNTA(procesniveau!J$2:J$2000) -> 4 | J34: =IF(D34="ja",COUNTA(procesniveau!$A$2:$A$2000)-I34,"") -> 0
A35: procesniveau | B35: version_number | C35: integer | D35: ja | H35: Versienummer van record | I35: =COUNTA(procesniveau!K$2:K$2000) -> 4 | J35: =IF(D35="ja",COUNTA(procesniveau!$A$2:$A$2000)-I35,"") -> 0
A36: procesniveau | B36: valid_from | C36: date | D36: nee | H36: Geldig vanaf | I36: =COUNTA(procesniveau!L$2:L$2000) -> 0 | J36: =IF(D36="ja",COUNTA(procesniveau!$A$2:$A$2000)-I36,"")
A37: procesniveau | B37: valid_until | C37: date | D37: nee | H37: Geldig tot | I37: =COUNTA(procesniveau!M$2:M$2000) -> 0 | J37: =IF(D37="ja",COUNTA(procesniveau!$A$2:$A$2000)-I37,"")
A38: procesniveau | B38: notes_internal | C38: text | D38: nee | H38: Interne beheerinformatie | I38: =COUNTA(procesniveau!N$2:N$2000) -> 4 | J38: =IF(D38="ja",COUNTA(procesniveau!$A$2:$A$2000)-I38,"")
A39: procesfase | B39: procesfase_id | C39: UUID | D39: ja | E39: PK | H39: Primaire sleutel | I39: =COUNTA(procesfase!A$2:A$2000) -> 12 | J39: =IF(D39="ja",COUNTA(procesfase!$A$2:$A$2000)-I39,"") -> 0
A40: procesfase | B40: procesniveau_id | C40: UUID, FK | D40: ja | E40: FK | F40: procesniveau.code | H40: Verwijzing naar procesniveau | I40: =COUNTA(procesfase!B$2:B$2000) -> 12 | J40: =IF(D40="ja",COUNTA(procesfase!$A$2:$A$2000)-I40,"") -> 0
A41: procesfase | B41: fase_code | C41: varchar(20) | D41: ja | H41: Bijvoorbeeld P3 of O4 | I41: =COUNTA(procesfase!C$2:C$2000) -> 12 | J41: =IF(D41="ja",COUNTA(procesfase!$A$2:$A$2000)-I41,"") -> 0
...

Sheet Keuzelijsten
A1: Keuzelijsten
A2: Eén kolom per keuzeveld. Nieuwe waarde: onderaan de kolom toevoegen, dan klopt de dropdown direct.
A4: (alle tabellen).record_status | B4: opgave.niveau_default | C4: procesfase_relatie.relatietype | D4: beslismoment.formaliteitsniveau | E4: beslismoment.voorbereidend_of_definitief | F4: rol.informatie_detailniveau | G4: knelpunt.knelpunttype | H4: instrument.zelfstandig_bruikbaar | I4: instrument.complexiteitsniveau | J4: instrument.doorlooptijd_categorie | K4: instrument.relevantie_v1 | L4: instrument_organisatie.relatierol | M4: instrument_bron.bronrol | N4: instrument_rol.rol_bij_gebruik | O4: instrument_beslismoment.ondersteuningsfunctie | P4: instrument_financiele_vraag.antwoordniveau | Q4: instrument_eigenaartype.toepasbaarheid | R4: instrument_voorwaarde.operator | S4: werkingsgebied.gebiedstype | T4: openstelling.openstelling_status | U4: beslismoment_rol.betrokkenheidstype | V4: beslismoment_rol.raci_type | W4: beslismoment_beslisproduct.productrol | X4: kennisproduct.relatie_met_kompas | Y4: validatie.validatiemethode | Z4: kennisanalyse.analysetype | AA4: gebruikersfeedback.feedbacktype
A5: actief | B5: portefeuille | C5: volgt op | D5: informeel | E5: voorbereidend | F5: strategisch | G5: ontbrekende informatie | H5: ja | I5: basis | J5: direct | K5: hoog | L5: eigenaar | M5: officiële bron | N5: gebruiker | O5: informeren | P5: eerste oriëntatie | Q5: direct toepasbaar | R5: gelijk aan | S5: Europees | T5: open | U5: initieert | V5: R | W5: input | X5: inhoud opnemen | Y5: broncontrole | Z5: witte vlek | AA5: inhoud onjuist
A6: concept | B6: programma | C6: kan volgen op | D6: ambtelijk | E6: richtinggevend | F6: tactisch | G6: onduidelijke verantwoordelijkheid | H6: deels | I6: gemiddeld | J6: dagen | K6: middel | L6: beheerder | M6: gebruiksinstructie | N6: adviseur | O6: analyseren | P6: indicatief inzicht | Q6: mogelijk toepasbaar | R6: niet gelijk aan | S6: landelijk | T6: gesloten | U6: bereidt voor | V6: A | W6: onderbouwing | X6: naar verwijzen | Y6: deskundigenreview | Z6: beperkte dekking | AA6: informatie verouderd
A7: gearchiveerd | B7: object | C7: keert terug naar | D7: bestuurlijk | E7: definitief | F7: operationeel | G7: overdrachtsprobleem | H7: nee | I7: specialistisch | J7: weken | K7: laag | L7: uitvoerder | M7: onderbouwing | N7: beslisser | O7: rekenen | P7: volledige onderbouwing | Q7: alleen via samenwerking | R7: groter dan | S7: provincie | T7: verwacht | U7: levert input | V7: C | W7: besluitdocument | X7: onderlegger | Y7: interview | Z7: mogelijke doublure | AA7: instrument ontbreekt
B8: project | C8: leidt parallel tot | D8: formeel | G8: ontbrekend instrument | H8: onbekend | J8: maanden | L8: verstrekker | M8: praktijktoepassing | N8: leverancier van input | O8: vergelijken | P8: specialistische onderbouwing | Q8: alleen via andere juridische entiteit | R8: kleiner dan | S8: regio | T8: doorlopend | U8: adviseert | V8: I | W8: output | X8: mogelijke toekomstige koppeling | Y8: gebruikerssessie | Z8: inhoudelijke overlap | AA8: niet begrijpelijk
C9: activeert | G9: onvoldoende capaciteit | L9: ontwikkelaar | M9: validatie | N9: toetser | O9: prioriteren | P9: verwijzing naar expertise | Q9: niet toepasbaar | R9: minimaal | S9: gemeente | T9: uitgeput | U9: toetst | W9: overdrachtsproduct | X9: buiten scope | Y9: casusvalidatie | Z9: regionale versnippering | AA9: route niet herkenbaar
C10: herijkt | G10: kennisprobleem | L10: inhoudelijk verantwoordelijke | M10: actualiteitscontrole | N10: beheerder | O10: toetsen | Q10: nog te controleren | R10: maximaal | S10: lokaal fonds | T10: beëindigd | U10: besluit | W10: monitoring | Y10: kernteam | Z10: sectorspecifieke variatie | AA10: onvoldoende handelingsperspectief
G11: lokaal procesverschil | L11: actualisatieverantwoordelijke | M11: achtergrondinformatie | N11: ontvanger van output | O11: financieren | R11: bevat | T11: onbekend | U11: voert uit | Y11: redactionele controle | Z11: verouderde informatie | AA11: koppeling onjuist
G12: mandaatprobleem | L12: kennispartner | O12: bekostigen | R12: geldt voor | U12: monitort | Y12: technische controle | Z12: onduidelijke bronhouder | AA12: positief praktijkvoorbeeld
G13: timing P&C-cyclus | L13: distributeur | O13: onderbouwen | R13: geldt niet voor | U13: wordt geïnformeerd | Z13: ontbrekend handelingsperspectief | AA13: verbetersuggestie
G14: onvoldoende dekking | O14: besluiten voorbereiden | R14: vereist | Z14: ontbrekende bestuurlijke vertaling
G15: fiscale of juridische onzekerheid | O15: contracteren | R15: optioneel | Z15: ontbrekende praktische toepassing
O16: monitoren
O17: verantwoorden
O18: herijken

Sheet Afwijkingen
A1: Afwijkingen en gaten in de modelbeschrijving
A2: Gaten in de modelbeschrijving, gemeld en niet opgelost; ongewijzigd t.o.v. de lege werkmap. Kolom 'Verwerking' verwijst naar de lege versie.
A4: Nr | B4: Onderwerp | C4: Bevinding | D4: Verwerking in deze werkmap | E4: Beslissing nodig van
A5: 1 | B5: opgave_beslismoment ontbreekt | C5: Het ER-model (§17) noemt de koppeltabel OPGAVE_BESLISMOMENT, maar die is nergens uitgewerkt. Een opgave is daardoor alleen aan instrument (instrument_opgave) en gebruikersfeedback gekoppeld, niet aan procesniveau, fase of beslismoment. De hoofdrelatie uit §2 (opgave -> procesniveau -> ... -> beslismoment) is zo niet af te leiden. | D5: Niet opgenomen. | E5: Kernteam
A6: 2 | B6: Hoofdrelatie §2 niet volledig gedekt | C6: De keten informatiebehoefte -> financiële vraag -> handelingsperspectief -> instrument heeft geen eigen relaties. Deze vier hangen elk alleen aan beslismoment (en deels aan rol). Welk instrument bij welk handelingsperspectief hoort, is niet vast te leggen. | D6: Geen extra koppeltabellen toegevoegd. | E6: Kernteam
A7: 3 | B7: procesniveau - beslismoment | C7: §17 toont PROCESNIVEAU 1-n BESLISMOMENT, maar beslismoment heeft alleen procesfase_id. Het niveau is alleen via de fase af te leiden. | D7: Tabel conform §4.5. | E7: Datamodelleur
A8: 4 | B8: Fasen alleen voor twee van vier niveaus | C8: procesniveau kent vier records (PORT, PROG, OBJ, PROJ), de voorgestelde fasen zijn alleen 'portefeuillefasen' (P) en 'objectfasen' (O). PROG en PROJ hebben geen fasen. | D8: P-fasen gekoppeld aan PORT, O-fasen aan OBJ. | E8: Kernteam (beslispunt 1 en 2)
A9: 5 | B9: Verplichte instrumentvelden §19 zonder plek | C9: §19 verplicht per instrument 'Primair procesniveau' en 'Benodigde expertise'. Het model kent geen relatie instrument-procesniveau en geen veld voor benodigde expertise (alleen als voorwaardetype 'vereiste expertise'). 'Laatste controledatum' bestaat alleen in openstelling en reviewplanning. | D9: Geen velden toegevoegd. | E9: Datamodelleur
A10: 6 | B10: Fasering §18 dekt niet alle tabellen | C10: §18 deelt 42 tabellen in; 23 uitgewerkte tabellen staan in geen enkele fase: procesfase_relatie, besluittype, rolcluster, functie_alias, informatietype, knelpunt, digitale_vorm, organisatietype, instrument_organisatie, brontype, instrument_opgave, financiele_route, instrument_financiele_route, instrument_werkingsgebied, pc_moment, beslismoment_knelpunt, instrument_relatietype, kennisproduct, kennisproduct_instrument, kennisproduct_beslismoment, publicatiestatus, inhoudelijke_status, ontwikkelactie. Daaronder keuzelijsttabellen waar verplichte velden uit fase 1 naar verwijzen (besluittype, rolcluster, organisatietype, brontype, publicatiestatus, inhoudelijke_status). | D10: Alle tabellen opgenomen; in kolom Fase gemarkeerd als 'niet ingedeeld'. | E10: Kernteam
A11: 7 | B11: Fase 1 versus verplichte velden §19 | C11: §19 verplicht bronhouder en werkingsgebied in versie 1.0, maar instrument_organisatie en instrument_werkingsgebied zijn niet ingedeeld en werkingsgebied staat in fase 3. | D11: Tabellen opgenomen en gevuld vanuit de catalogus. | E11: Kernteam
A12: 8 | B12: Tabellen zonder veldbeschrijving | C12: organisatietype, brontype, instrument_relatietype, publicatiestatus en inhoudelijke_status hebben in de tekst alleen waarden, geen velden. | D12: Aanname: sleutel, code, naam, omschrijving, sort_order plus beheervelden, naar het patroon van de andere keuzelijsttabellen. Dit is de enige structurele aanvulling. | E12: Datamodelleur
A13: 9 | B13: Keuzevelden zonder waardenlijst | C13: Voor 42 velden met een beperkte waardenset geeft de tekst geen waarden, waaronder alle velden relevantie, prioriteit, impact, status en entity_type. Zie kolom Keuzelijst op tabblad Velden. | D13: Geen dropdown; vrij invulbaar. Bij de migratie zijn deze velden leeg gelaten. | E13: Kernteam
A14: 10 | B14: Toepasbaarheid bij objecttype | C14: De waarden voor toepasbaarheid staan alleen onder §7.6 (eigenaartype). §7.7 (objecttype) heeft hetzelfde veld zonder lijst. | D14: Aanname: dezelfde lijst gebruikt. | E14: Datamodelleur
A15: 11 | B15: Verwijzingen via entity_type/entity_id | C15: validatie, wijzigingslog, reviewplanning en gebruikersfeedback verwijzen naar 'een' record via entity_type en entity_id. Een database kan dat niet als verwijzing afdwingen, en de toegestane waarden voor entity_type zijn niet gegeven. | D15: Conform tekst; geen dropdown. | E15: Datamodelleur
A16: 12 | B16: Naamgeving sleutels | C16: Niet alle sleutels volgen het patroon tabelnaam_id: beslismoment_informatiebehoefte heeft beslismoment_informatie_id, gebruikersfeedback heeft feedback_id, instrument_relatie verwijst met relatietype_id naar instrument_relatietype. validation_status is Engels, de rest Nederlands. | D16: Namen letterlijk overgenomen. | E16: Datamodelleur
... A24: 20 | B24: Catalogus v0.1: rollen | C24: De catalogus kent zeven rollen, waarvan twee eigenaartypen zijn en twee samengesteld (Vastgoedexpert/PM, Financieel medewerker/controller). Alleen 'Wethouder' past eenduidig; 8 rolkoppelingen zijn overgenomen, 129 niet. | D24: Zie Migratie_rest. | E24: Kernteam (beslispunt 4)

Sheet opgave
A1: opgave_id | B1: opgave_code | C1: naam | D1: korte_omschrijving | E1: uitgebreide_omschrijving | F1: aanleiding | G1: gewenst_resultaat | H1: niveau_default | I1: primaire_doelgroep | J1: sort_order | K1: is_public | L1: created_at | M1: created_by | N1: updated_at | O1: updated_by | P1: record_status | Q1: version_number | R1: valid_from | S1: valid_until | T1: notes_internal
A2: edb80e5b-7c99-518b-b3a3-759d248a8884 | B2: OPG-001 | C2: verduurzamingsopgave bepalen | D2: Bepaal hoe groot de verduurzamingsopgave van het vastgoed is | G2: Dummy: een onderbouwd antwoord op: verduurzamingsopgave bepalen. | H2: portefeuille | J2: 1 | K2: ja | L2: 2026-10-02 | M2: startwaardelijst datamodel | N2: 2026-10-02 | O2: startwaardelijst datamodel | P2: concept | Q2: 1 | T2: DUMMY-aanvulling: gewenst_resultaat, is_public, korte_omschrijving, niveau_default
A3: b81ebeab-5b54-59b4-891d-f4025c6913d0 | B3: OPG-002 | C3: portefeuille prioriteren | D3: Rangschik de objecten en kies wat eerst komt | G3: Dummy: een onderbouwd antwoord op: portefeuille prioriteren. | H3: portefeuille | J3: 2 | K3: ja | L3: 2026-10-02 | M3: startwaardelijst datamodel | N3: 2026-10-02 | O3: startwaardelijst datamodel | P3: concept | Q3: 1 | T3: DUMMY-aanvulling: gewenst_resultaat, is_public, korte_omschrijving, niveau_default
A4: d905a0f8-2cd6-5974-98fb-476e0c50784d | B4: OPG-003 | C4: uitvoeringsprogramma opstellen | D4: Maak een uitvoeringsprogramma binnen het budget | G4: Dummy: een onderbouwd antwoord op: uitvoeringsprogramma opstellen. | H4: programma | J4: 3 | K4: ja | L4: 2026-10-02 | M4: startwaardelijst datamodel | N4: 2026-10-02 | O4: startwaardelijst datamodel | P4: concept | Q4: 1 | T4: DUMMY-aanvulling: gewenst_resultaat, is_public, korte_omschrijving, niveau_default
A5: fd32baca-8921-552c-ad52-bb3e45699f95 | B5: OPG-004 | C5: object verduurzamen | D5: Pak een gebouw aan en verduurzaam het | G5: Dummy: een onderbouwd antwoord op: object verduurzamen. | H5: object | J5: 4 | K5: ja | L5: 2026-10-02 | M5: startwaardelijst datamodel | N5: 2026-10-02 | O5: startwaardelijst datamodel | P5: concept | Q5: 1 | T5: DUMMY-aanvulling: gewenst_resultaat, is_public, korte_omschrijving, niveau_default
A6: 42faaa98-a334-5a17-a076-7e4adb9060ad | B6: OPG-005 | C6: accommodatie vernieuwen | D6: Vernieuw een accommodatie | G6: Dummy: een onderbouwd antwoord op: accommodatie vernieuwen. | H6: object | J6: 5 | K6: ja | L6: 2026-10-02 | M6: startwaardelijst datamodel | N6: 2026-10-02 | O6: startwaardelijst datamodel | P6: concept | Q6: 1 | T6: DUMMY-aanvulling: gewenst_resultaat, is_public, korte_omschrijving, niveau_default
A7: 81f58067-24f9-57d4-9965-81cd84523e78 | B7: OPG-006 | C7: investering voorbereiden | D7: Bereid een investering voor | G7: Dummy: een onderbouwd antwoord op: investering voorbereiden. | H7: object | J7: 6 | K7: ja | L7: 2026-10-02 | M7: startwaardelijst datamodel | N7: 2026-10-02 | O7: startwaardelijst datamodel | P7: concept | Q7: 1 | T7: DUMMY-aanvulling: gewenst_resultaat, is_public, korte_omschrijving, niveau_default
A8: cfd5d161-bf93-5067-94e8-3f68474da126 | B8: OPG-007 | C8: financiering of dekking organiseren | D8: Organiseer financiering of dekking | G8: Dummy: een onderbouwd antwoord op: financiering of dekking organiseren. | H8: object | J8: 7 | K8: ja | L8: 2026-10-02 | M8: startwaardelijst datamodel | N8: 2026-10-02 | O8: startwaardelijst datamodel | P8: concept | Q8: 1 | T8: DUMMY-aanvulling: gewenst_resultaat, is_public, korte_omschrijving, niveau_default
A9: 4ebb3bc7-232d-5a64-bb0d-54fd09a52ee4 | B9: OPG-008 | C9: exploitatie verbeteren | D9: Verbeter de exploitatie van een gebouw | G9: Dummy: een onderbouwd antwoord op: exploitatie verbeteren. | H9: object | J9: 8 | K9: ja | L9: 2026-10-02 | M9: startwaardelijst datamodel | N9: 2026-10-02 | O9: startwaardelijst datamodel | P9: concept | Q9: 1 | T9: DUMMY-aanvulling: gewenst_resultaat, is_public, korte_omschrijving, niveau_default
A10: d7f5569c-48f8-5414-a819-7c1bce611e56 | B10: OPG-009 | C10: prestaties monitoren | D10: Volg de prestaties van het vastgoed | G10: Dummy: een onderbouwd antwoord op: prestaties monitoren. | H10: portefeuille | J10: 9 | K10: ja | L10: 2026-10-02 | M10: startwaardelijst datamodel | N10: 2026-10-02 | O10: startwaardelijst datamodel | P10: concept | Q10: 1 | T10: DUMMY-aanvulling: gewenst_resultaat, is_public, korte_omschrijving, niveau_default
A11: 7a0bcf2c-029c-5f0b-af97-854948b9e324 | B11: OPG-010 | C11: strategie herijken | D11: Herijk de vastgoedstrategie | G11: Dummy: een onderbouwd antwoord op: strategie herijken. | H11: portefeuille | J11: 10 | K11: ja | L11: 2026-10-02 | M11: startwaardelijst datamodel | N11: 2026-10-02 | O11: startwaardelijst datamodel | P11: concept | Q11: 1 | T11: DUMMY-aanvulling: gewenst_resultaat, is_public, korte_omschrijving, niveau_default

Sheet procesniveau
A1: procesniveau_id | B1: code | C1: naam | D1: omschrijving | E1: sort_order | F1: created_at | G1: created_by | H1: updated_at | I1: updated_by | J1: record_status | K1: version_number | L1: valid_from | M1: valid_until | N1: notes_internal
A2: 6e830033-beab-52ff-af50-47b90185a425 | B2: PORT | C2: Portefeuille | D2: Alle objecten van de organisatie samen: strategie, prioritering en meerjarig budget. | E2: 1 | F2: 2026-10-02 | G2: startwaardelijst datamodel | H2: 2026-10-02 | I2: startwaardelijst datamodel | J2: concept | K2: 1 | N2: DUMMY-aanvulling: omschrijving
A3: ce6ba184-fd57-5f93-966f-25855310460f | B3: PROG | C3: Programma | D3: Een samenhangende set projecten met gezamenlijke doelen, planning en budget. | E3: 2 | F3: 2026-10-02 | G3: startwaardelijst datamodel | H3: 2026-10-02 | I3: startwaardelijst datamodel | J3: concept | K3: 1 | N3: DUMMY-aanvulling: omschrijving
A4: a271a421-b3e3-5ea3-9e2b-b3caaeffe7c9 | B4: OBJ | C4: Object | D4: Eén gebouw of accommodatie, van initiatief tot exploitatie. | E4: 3 | F4: 2026-10-02 | G4: startwaardelijst datamodel | H4: 2026-10-02 | I4: startwaardelijst datamodel | J4: concept | K4: 1 | N4: DUMMY-aanvulling: omschrijving
A5: d62e9efa-e217-50c8-9844-9454ec7dc140 | B5: PROJ | C5: Project | D5: Een afgebakende ingreep aan een object, zoals een verduurzamingsproject. | E5: 4 | F5: 2026-10-02 | G5: startwaardelijst datamodel | H5: 2026-10-02 | I5: startwaardelijst datamodel | J5: concept | K5: 1 | N5: DUMMY-aanvulling: omschrijving

Sheet procesfase
A1: procesfase_id | B1: procesniveau_id | C1: fase_code | D1: naam | E1: centrale_vraag | F1: omschrijving | G1: startcriterium | H1: eindcriterium | I1: standaard_resultaat | J1: sort_order | K1: is_work_hypothesis | L1: validation_status_id | M1: created_at | N1: created_by | O1: updated_at | P1: updated_by | Q1: record_status | R1: version_number | S1: valid_from | T1: valid_until | U1: notes_internal
A2: 1f3bb4ac-0700-56fc-bb41-1902287c72e8 | B2: PORT | C2: P1 | D2: Richting en kaders | E2: Welke ambitie en financiële kaders gelden voor ons vastgoed? | F2: Bestuurlijke richting en kaders voor het vastgoedbeleid. | G2: Aanleiding: nieuw college of nieuwe opgave. | H2: Kaders zijn vastgesteld. | I2: Vastgestelde ambitie en kaders | J2: 1 | K2: ja | L2: VS-02 | M2: 2026-10-02 | N2: startwaardelijst datamodel | O2: 2026-10-02 | P2: startwaardelijst datamodel | Q2: concept | R2: 1 | U2: DUMMY-aanvulling: centrale_vraag, eindcriterium, omschrijving, standaard_resultaat, startcriterium, validation_status_id
A3: 0730b6b8-6f18-59d6-a261-68951875f3d4 | B3: PORT | C3: P2 | D3: Inzicht en analyse | E3: Wat is de stand van de portefeuille en wat kost niets doen? | F3: Inzicht in staat, kosten en prestaties van alle objecten. | G3: Kaders zijn vastgesteld. | H3: Nulmeting is geaccordeerd. | I3: Portefeuilleanalyse met nulmeting | J3: 2 | K3: ja | L3: VS-02 | M3: 2026-10-02 | N3: startwaardelijst datamodel | O3: 2026-10-02 | P3: startwaardelijst datamodel | Q3: concept | R3: 1 | U3: DUMMY-aanvulling: centrale_vraag, eindcriterium, omschrijving, standaard_resultaat, startcriterium, validation_status_id
A4: c3370122-9e82-51c0-ae4a-56dff990586c | B4: PORT | C4: P3 | D4: Portefeuillestrategie en programmering | E4: Welke prioriteiten en welk programma passen binnen de middelen? | F4: Prioriteren van objecten en programmeren in de tijd binnen het budget. | G4: Nulmeting is geaccordeerd. | H4: Programma met dekking is vastgesteld. | I4: Prioriteitenlijst en meerjarenprogramma | J4: 3 | K4: ja | L4: VS-02 | M4: 2026-10-02 | N4: startwaardelijst datamodel | O4: 2026-10-02 | P4: startwaardelijst datamodel | Q4: concept | R4: 1 | U4: DUMMY-aanvulling: centrale_vraag, eindcriterium, omschrijving, standaard_resultaat, startcriterium, validation_status_id
A5: b3319dde-7f4a-5fa3-8bbc-1b150950feaf | B5: PORT | C5: P4 | D5: Uitvoering portefeuille | E5: Hoe wordt het programma uitgevoerd en gefinancierd? | F5: Uitvoering van de jaarschijven en inzet van financiering. | G5: Programma is vastgesteld. | H5: Jaarschijf is afgerond. | I5: Uitgevoerde jaarschijf | J5: 4 | K5: ja | L5: VS-02 | M5: 2026-10-02 | N5: startwaardelijst datamodel | O5: 2026-10-02 | P5: startwaardelijst datamodel | Q5: concept | R5: 1 | U5: DUMMY-aanvulling: centrale_vraag, eindcriterium, omschrijving, standaard_resultaat, startcriterium, validation_status_id
A6: 039fc579-3c78-5be0-8918-16e085a42591 | B6: PORT | C6: P5 | D6: Monitoren en herijken | E6: Halen we de doelen en moet de strategie worden herijkt? | F6: Volgen van voortgang en prestaties, bijsturen en herijken. | G6: Eerste jaarschijf is afgerond. | H6: Herijking is vastgesteld. | I6: Monitoringsrapportage en herijkingsvoorstel | J6: 5 | K6: ja | L6: VS-02 | M6: 2026-10-02 | N6: startwaardelijst datamodel | O6: 2026-10-02 | P6: startwaardelijst datamodel | Q6: concept | R6: 1 | U6: DUMMY-aanvulling: centrale_vraag, eindcriterium, omschrijving, standaard_resultaat, startcriterium, validation_status_id
A7: c9cee471-85c8-5e09-bea3-9d8bfdf23178 | B7: OBJ | C7: O1 | D7: Trigger en initiatief | E7: Is er aanleiding om dit object aan te pakken? | F7: Trigger en initiatief voor een object. | G7: Er is een aanleiding of opdracht. | H7: Projectopdracht verkenning is verstrekt. | I7: Projectopdracht verkenning | J7: 1 | K7: ja | L7: VS-02 | M7: 2026-10-02 | N7: startwaardelijst datamodel | O7: 2026-10-02 | P7: startwaardelijst datamodel | Q7: concept | R7: 1 | U7: DUMMY-aanvulling: centrale_vraag, eindcriterium, omschrijving, standaard_resultaat, startcriterium, validation_status_id
A8: 90e47428-c6bb-5ee9-aee2-433b0d46f925 | B8: OBJ | C8: O2 | D8: Verkenning en haalbaarheid | E8: Is het haalbaar en welke varianten zijn er? | F8: Verkenning van varianten en haalbaarheid. | G8: Projectopdracht is verstrekt. | H8: Varianten zijn beoordeeld. | I8: Scenariovergelijking | J8: 2 | K8: ja | L8: VS-02 | M8: 2026-10-02 | N8: startwaardelijst datamodel | O8: 2026-10-02 | P8: startwaardelijst datamodel | Q8: concept | R8: 1 | U8: DUMMY-aanvulling: centrale_vraag, eindcriterium, omschrijving, standaard_resultaat, startcriterium, validation_status_id
A9: bd67a801-9c90-510a-bf78-31663f607f42 | B9: OBJ | C9: O3 | D9: Definitie en voorkeurskeuze | E9: Welke variant heeft de voorkeur en wat is het budget? | F9: Definitie van het project en keuze van de voorkeursvariant. | G9: Varianten zijn beoordeeld. | H9: Voorkeursbesluit is genomen. | I9: Voorkeursbesluit en budget | J9: 3 | K9: ja | L9: VS-02 | M9: 2026-10-02 | N9: startwaardelijst datamodel | O9: 2026-10-02 | P9: startwaardelijst datamodel | Q9: concept | R9: 1 | U9: DUMMY-aanvulling: centrale_vraag, eindcriterium, omschrijving, standaard_resultaat, startcriterium, validation_status_id
A10: 83dfd909-b86c-5b6b-9aca-48c3ddcc5de2 | B10: OBJ | C10: O4 | D10: Ontwerp en investeringsbesluit | E10: Is de investering onderbouwd en gedekt zodat het besluit genomen kan worden? | F10: Ontwerp, financiële onderbouwing en investeringsbesluit. | G10: Voorkeursbesluit is genomen. | H10: Krediet is beschikbaar gesteld. | I10: Investeringsvoorstel en krediet | J10: 4 | K10: ja | L10: VS-02 | M10: 2026-10-02 | N10: startwaardelijst datamodel | O10: 2026-10-02 | P10: startwaardelijst datamodel | Q10: concept | R10: 1 | U10: DUMMY-aanvulling: centrale_vraag, eindcriterium, omschrijving, standaard_resultaat, startcriterium, validation_status_id
A11: dc6aaf7b-7621-52eb-a006-e152df1bde2b | B11: OBJ | C11: O5 | D11: Contractering en realisatie | E11: Hoe wordt gecontracteerd en wat kost de realisatie? | F11: Aanbesteding, contractering en realisatie. | G11: Krediet is beschikbaar gesteld. | H11: Project is gerealiseerd. | I11: Contract en gerealiseerd project | J11: 5 | K11: ja | L11: VS-02 | M11: 2026-10-02 | N11: startwaardelijst datamodel | O11: 2026-10-02 | P11: startwaardelijst datamodel | Q11: concept | R11: 1 | U11: DUMMY-aanvulling: centrale_vraag, eindcriterium, omschrijving, standaard_resultaat, startcriterium, validation_status_id
A12: 7dcb0b2f-1cf3-5032-a045-ec438705e570 | B12: OBJ | C12: O6 | D12: Oplevering en ingebruikname | E12: Is het opgeleverd conform afspraken en wat zijn de beheerkosten? | F12: Oplevering, acceptatie en ingebruikname. | G12: Realisatie is gereed. | H12: Object is in gebruik genomen. | I12: Opleverdossier | J12: 6 | K12: ja | L12: VS-02 | M12: 2026-10-02 | N12: startwaardelijst datamodel | O12: 2026-10-02 | P12: startwaardelijst datamodel | Q12: concept | R12: 1 | U12: DUMMY-aanvulling: centrale_vraag, eindcriterium, omschrijving, standaard_resultaat, startcriterium, validation_status_id
A13: 27a18e93-6a34-5e33-aed2-bb296bc9fec5 | B13: OBJ | C13: O7 | D13: Exploitatie, beheer en evaluatie | E13: Presteert het object zoals bedoeld en wat leren we? | F13: Exploitatie, beheer en evaluatie. | G13: Object is in gebruik. | H13: Evaluatie is afgerond. | I13: Evaluatie en prestatiegegevens | J13: 7 | K13: ja | L13: VS-02 | M13: 2026-10-02 | N13: startwaardelijst datamodel | O13: 2026-10-02 | P13: startwaardelijst datamodel | Q13: concept | R13: 1 | U13: DUMMY-aanvulling: centrale_vraag, eindcriterium, omschrijving, standaard_resultaat, startcriterium, validation_status_id

Sheet procesfase_relatie
A1: procesfase_relatie_id | B1: van_procesfase_id | C1: naar_procesfase_id | D1: relatietype | E1: voorwaarde | F1: is_default_route | G1: sort_order | H1: created_at | I1: created_by | J1: updated_at | K1: updated_by | L1: record_status | M1: version_number | N1: valid_from | O1: valid_until | P1: notes_internal
A2: 1371438d-0004-5bb2-88bd-72c29e14a8b1 | B2: P1 | C2: P2 | D2: volgt op | F2: ja | G2: 1 | H2: 2026-10-03 | I2: dummy-generator | J2: 2026-10-03 | K2: dummy-generator | L2: concept | M2: 1 | P2: DUMMY
A3: 8a4852a9-eb1b-5c87-b731-840b39a01862 | B3: P2 | C3: P3 | D3: volgt op | F3: ja | G3: 2 | H3: 2026-10-03 | I3: dummy-generator | J3: 2026-10-03 | K3: dummy-generator | L3: concept | M3: 1 | P3: DUMMY
A4: c93db876-841c-5932-b776-d876505b91f4 | B4: P3 | C4: P4 | D4: volgt op | F4: ja | G4: 3 | H4: 2026-10-03 | I4: dummy-generator | J4: 2026-10-03 | K4: dummy-generator | L4: concept | M4: 1 | P4: DUMMY
A5: fd68bec1-107d-532d-91a4-d34285923952 | B5: P4 | C5: P5 | D5: volgt op | F5: ja | G5: 4 | H5: 2026-10-03 | I5: dummy-generator | J5: 2026-10-03 | K5: dummy-generator | L5: concept | M5: 1 | P5: DUMMY
A6: 6d18511e-9738-50d8-a4cd-b276d4cde4ca | B6: P5 | C6: P3 | D6: herijkt | F6: nee | G6: 5 | H6: 2026-10-03 | I6: dummy-generator | J6: 2026-10-03 | K6: dummy-generator | L6: concept | M6: 1 | P6: DUMMY
A7: 1bdb4df5-f8bf-5152-bc21-b4b64d2bf214 | B7: P5 | C7: P1 | D7: keert terug naar | F7: nee | G7: 6 | H7: 2026-10-03 | I7: dummy-generator | J7: 2026-10-03 | K7: dummy-generator | L7: concept | M7: 1 | P7: DUMMY
A8: 367da0c6-c5cc-51fa-acf9-3b0f468989a7 | B8: P3 | C8: O1 | D8: activeert | E8: Dummy: alleen als het object in het programma is opgenomen | F8: nee | G8: 7 | H8: 2026-10-03 | I8: dummy-generator | J8: 2026-10-03 | K8: dummy-generator | L8: concept | M8: 1 | P8: DUMMY
A9: ce89a7d5-4eae-5724-a3e8-713cf90d1a0d | B9: P4 | C9: O1 | D9: activeert | E9: Dummy: alleen als het object in het programma is opgenomen | F9: nee | G9: 8 | H9: 2026-10-03 | I9: dummy-generator | J9: 2026-10-03 | K9: dummy-generator | L9: concept | M9: 1 | P9: DUMMY
A10: b0c806bd-8eda-5eeb-9b6b-462d6e477634 | B10: O1 | C10: O2 | D10: volgt op | F10: ja | G10: 9 | H10: 2026-10-03 | I10: dummy-generator | J10: 2026-10-03 | K10: dummy-generator | L10: concept | M10: 1 | P10: DUMMY
A11: 65268cea-3ce2-5fd5-a598-0fc7d92127d0 | B11: O2 | C11: O3 | D11: volgt op | F11: ja | G11: 10 | H11: 2026-10-03 | I11: dummy-generator | J11: 2026-10-03 | K11: dummy-generator | L11: concept | M11: 1 | P11: DUMMY
A12: c73360a4-fb18-5b27-b228-1092ffdcfdea | B12: O3 | C12: O4 | D12: volgt op | F12: ja | G12: 11 | H12: 2026-10-03 | I12: dummy-generator | J12: 2026-10-03 | K12: dummy-generator | L12: concept | M12: 1 | P12: DUMMY
A13: b18d1a4e-2645-568c-8cb7-3758831044dc | B13: O4 | C13: O5 | D13: volgt op | F13: ja | G13: 12 | H13: 2026-10-03 | I13: dummy-generator | J13: 2026-10-03 | K13: dummy-generator | L13: concept | M13: 1 | P13: DUMMY
A14: a9458a2e-2bff-56fb-8dc3-66813d99f978 | B14: O5 | C14: O6 | D14: volgt op | F14: ja | G14: 13 | H14: 2026-10-03 | I14: dummy-generator | J14: 2026-10-03 | K14: dummy-generator | L14: concept | M14: 1 | P14: DUMMY
A15: bcc79bbd-962d-5e59-9fdc-9eb1e688de4c | B15: O6 | C15: O7 | D15: volgt op | F15: ja | G15: 14 | H15: 2026-10-03 | I15: dummy-generator | J15: 2026-10-03 | K15: dummy-generator | L15: concept | M15: 1 | P15: DUMMY
A16: 6c942830-bfc9-528a-a079-4b507daed2c7 | B16: O4 | C16: O3 | D16: keert terug naar | F16: nee | G16: 15 | H16: 2026-10-03 | I16: dummy-generator | J16: 2026-10-03 | K16: dummy-generator | L16: concept | M16: 1 | P16: DUMMY
A17: e733d728-fc1b-58b5-90a5-a1744ccbea5c | B17: O7 | C17: P5 | D17: leidt parallel tot | F17: nee | G17: 16 | H17: 2026-10-03 | I17: dummy-generator | J17: 2026-10-03 | K17: dummy-generator | L17: concept | M17: 1 | P17: DUMMY

Sheet beslismoment
A1: beslismoment_id | B1: beslismoment_code | C1: procesfase_id | D1: naam | E1: centrale_vraag | F1: omschrijving | G1: besluittype_id | H1: formaliteitsniveau | I1: voorbereidend_of_definitief | J1: verwacht_besluit | K1: benodigde_input_samenvatting | L1: verwachte_output | M1: volgende_stap | N1: mandaat_lokaal_bepaald | O1: pc_moment_id | P1: is_generic | Q1: is_work_hypothesis | R1: validation_status_id | S1: created_at | T1: created_by | U1: updated_at | V1: updated_by | W1: record_status | X1: version_number | Y1: valid_from | Z1: valid_until | AA1: notes_internal
A2: 6156f938-eb57-5d0a-aca9-92688e9bcaab | B2: BM-P1-01 | C2: P1 | D2: Ambitie en financiële kaders vaststellen | E2: Welke ambitie en financiële kaders gelden voor ons vastgoed? | F2: Dummy: vaststellen van ambitie en kaders. | G2: BT-03 | H2: bestuurlijk | I2: richtinggevend | J2: Vaststellen van ambitie en kaders | K2: Beleidskaders, ambities, financiële ruimte | L2: Raadsvoorstel kaders vastgoed | M2: Inzicht en analyse opstarten | N2: ja | O2: PC-01 | P2: ja | Q2: ja | R2: VS-02 | S2: 2026-10-03 | T2: dummy-generator | U2: 2026-10-03 | V2: dummy-generator | W2: concept | X2: 1 | AA2: DUMMY
A3: 98f00286-5111-5f2a-9044-b3254bc5b88d | B3: BM-P2-01 | C3: P2 | D3: Opgave en nulmeting accorderen | E3: Wat is de stand van de portefeuille en wat kost niets doen? | F3: Dummy: accorderen van de nulmeting. | G3: BT-01 | H3: ambtelijk | I3: voorbereidend | J3: Accorderen van de nulmeting | K3: Portefeuilledata, onderhoudsstaat, energielabels | L3: Portefeuilleanalyse met nulmeting | M3: Prioriteiten stellen | N3: nee | O3: PC-10 | P3: ja | Q3: ja | R3: VS-02 | S3: 2026-10-03 | T3: dummy-generator | U3: 2026-10-03 | V3: dummy-generator | W3: concept | X3: 1 | AA3: DUMMY
A4: e82f7080-2cfc-5f28-9944-8f427118fd8d | B4: BM-P3-01 | C4: P3 | D4: Prioriteiten stellen | E4: Welke objecten pakken we eerst aan en op basis waarvan? | F4: Dummy: vaststellen van de prioriteitenlijst. | G4: BT-04 | H4: ambtelijk | I4: richtinggevend | J4: Vaststellen van de prioriteitenlijst | K4: Nulmeting, afwegingscriteria, maatschappelijke waarde | L4: Prioriteitenlijst | M4: Meerjarenprogramma opstellen | N4: nee | O4: PC-10 | P4: ja | Q4: ja | R4: VS-02 | S4: 2026-10-03 | T4: dummy-generator | U4: 2026-10-03 | V4: dummy-generator | W4: concept | X4: 1 | AA4: DUMMY
A5: 51475306-097e-5cb8-bef7-0519fbd30abd | B5: BM-P3-02 | C5: P3 | D5: Meerjarenprogramma en dekking vaststellen | E5: Welk programma past binnen de beschikbare middelen en hoe is het gedekt? | F5: Dummy: vaststellen van programma en dekking. | G5: BT-05 | H5: bestuurlijk | I5: definitief | J5: Vaststellen van programma en dekking | K5: Begrotingsruimte, boekwaarde, ramingen | L5: Collegevoorstel programma | M5: Jaarschijf vrijgeven | N5: ja | O5: PC-02 | P5: ja | Q5: ja | R5: VS-02 | S5: 2026-10-03 | T5: dummy-generator | U5: 2026-10-03 | V5: dummy-generator | W5: concept | X5: 1 | AA5: DUMMY
A6: cafef713-5fb3-5519-a769-8b45ceedf668 | B6: BM-P4-01 | C6: P4 | D6: Jaarschijf en uitvoeringsbudget vrijgeven | E6: Welk budget geven we dit jaar vrij en hoe financieren we het? | F6: Dummy: vrijgeven van jaarschijf. | G6: BT-08 | H6: bestuurlijk | I6: definitief | J6: Vrijgeven van jaarschijf | K6: Programma, ramingen, subsidiemogelijkheden | L6: Kredietaanvraag jaarschijf | M6: Uitvoering starten | N6: ja | O6: PC-04 | P6: ja | Q6: ja | R6: VS-02 | S6: 2026-10-03 | T6: dummy-generator | U6: 2026-10-03 | V6: dummy-generator | W6: concept | X6: 1 | AA6: DUMMY
A7: 8ae20795-1191-5505-8e12-d9d75fdc5689 | B7: BM-P5-01 | C7: P5 | D7: Voortgang en prestaties beoordelen | E7: Halen we de doelen en blijft het binnen budget? | F7: Dummy: bijsturen van het programma. | G7: BT-12 | H7: ambtelijk | I7: voorbereidend | J7: Bijsturen van het programma | K7: Voortgangs- en prestatiegegevens | L7: Monitoringsrapportage | M7: Strategie herijken | N7: nee | O7: PC-06 | P7: ja | Q7: ja | R7: VS-02 | S7: 2026-10-03 | T7: dummy-generator | U7: 2026-10-03 | V7: dummy-generator | W7: concept | X7: 1 | AA7: DUMMY
A8: 16f6beb3-d778-5595-a11b-2f796ba15a47 | B8: BM-P5-02 | C8: P5 | D8: Strategie herijken | E8: Moeten ambitie, kaders of programma worden aangepast? | F8: Dummy: herijken van strategie. | G8: BT-13 | H8: bestuurlijk | I8: definitief | J8: Herijken van strategie | K8: Monitoringsrapportage, beleidskaders | L8: Herijkingsvoorstel | M8: Nieuwe kaders vaststellen | N8: ja | O8: PC-01 | P8: ja | Q8: ja | R8: VS-02 | S8: 2026-10-03 | T8: dummy-generator | U8: 2026-10-03 | V8: dummy-generator | W8: concept | X8: 1 | AA8: DUMMY
A9: 6fa07aba-e44a-57f3-8dcc-f08cb18e7af6 | B9: BM-O1-01 | C9: O1 | D9: Initiatief starten | E9: Is er aanleiding om dit object aan te pakken? | F9: Dummy: starten van verkenning. | G9: BT-01 | H9: ambtelijk | I9: voorbereidend | J9: Starten van verkenning | K9: Onderhoudsstaat, gebruikerswensen | L9: Projectopdracht verkenning | M9: Haalbaarheid onderzoeken | N9: nee | O9: PC-11 | P9: ja | Q9: ja | R9: VS-02 | S9: 2026-10-03 | T9: dummy-generator | U9: 2026-10-03 | V9: dummy-generator | W9: concept | X9: 1 | AA9: DUMMY
A10: 89a2c493-046c-5938-87f3-635fbac99248 | B10: BM-O2-01 | C10: O2 | D10: Haalbaarheid en varianten beoordelen | E10: Is het haalbaar en welke varianten zijn er? | F10: Dummy: beoordelen van varianten. | G10: BT-06 | H10: ambtelijk | I10: voorbereidend | J10: Beoordelen van varianten | K10: Ramingen, exploitatie, juridische afspraken | L10: Scenariovergelijking | M10: Voorkeursvariant kiezen | N10: nee | P10: ja | Q10: ja | R10: VS-02 | S10: 2026-10-03 | T10: dummy-generator | U10: 2026-10-03 | V10: dummy-generator | W10: concept | X10: 1 | AA10: DUMMY
A11: e58bb9c6-4ed0-540b-ae41-7a7971ec2ed8 | B11: BM-O3-01 | C11: O3 | D11: Voorkeursvariant kiezen | E11: Welke variant heeft de voorkeur en wat is het budget? | F11: Dummy: kiezen van voorkeursvariant. | G11: BT-02 | H11: bestuurlijk | I11: richtinggevend | J11: Kiezen van voorkeursvariant | K11: Scenariovergelijking, maatschappelijk effect | L11: Voorkeursbesluit | M11: Ontwerp en financiële beoordeling | N11: ja | P11: ja | Q11: ja | R11: VS-02 | S11: 2026-10-03 | T11: dummy-generator | U11: 2026-10-03 | V11: dummy-generator | W11: concept | X11: 1 | AA11: DUMMY
A12: 6988526b-d463-523d-afaf-955c812cc5db | B12: BM-O4-01 | C12: O4 | D12: Voorkeursvariant financieel beoordelen | E12: Welke variant is over de levensduur het meest betaalbaar? | F12: Dummy: financiële toets van de voorkeursvariant. | G12: BT-06 | H12: ambtelijk | I12: voorbereidend | J12: Financiële toets van de voorkeursvariant | K12: Ramingen, TCO, boekwaarde, fiscale positie, risico's | L12: Investeringsvoorstel | M12: Investeringsbesluit voorbereiden | N12: nee | P12: ja | Q12: ja | R12: VS-02 | S12: 2026-10-03 | T12: dummy-generator | U12: 2026-10-03 | V12: dummy-generator | W12: concept | X12: 1 | AA12: DUMMY
A13: 49658117-4a7a-5431-a76a-d0409513ed1b | B13: BM-O4-02 | C13: O4 | D13: Investeringsbesluit nemen | E13: Nemen we het investeringsbesluit en onder welke voorwaarden? | F13: Dummy: nemen van investeringsbesluit. | G13: BT-07 | H13: bestuurlijk | I13: definitief | J13: Nemen van investeringsbesluit | K13: Investeringsvoorstel, bestuurlijke beslisinformatie | L13: Collegevoorstel en raadsvoorstel | M13: Krediet en dekking regelen | N13: ja | O13: PC-05 | P13: ja | Q13: ja | R13: VS-02 | S13: 2026-10-03 | T13: dummy-generator | U13: 2026-10-03 | V13: dummy-generator | W13: concept | X13: 1 | AA13: DUMMY
A14: c7eb949e-1c44-52b7-95d9-5726d80bec34 | B14: BM-O4-03 | C14: O4 | D14: Krediet en dekking regelen | E14: Is het krediet beschikbaar en is de dekking geregeld? | F14: Dummy: beschikbaar stellen van krediet. | G14: BT-08 | H14: formeel | I14: definitief | J14: Beschikbaar stellen van krediet | K14: Begrotingsruimte, subsidiebeschikkingen, leningaanbod | L14: Kredietaanvraag | M14: Aanbesteden | N14: ja | O14: PC-04 | P14: ja | Q14: ja | R14: VS-02 | S14: 2026-10-03 | T14: dummy-generator | U14: 2026-10-03 | V14: dummy-generator | W14: concept | X14: 1 | AA14: DUMMY
A15: db17631f-2449-54e2-b4d7-ebfc8c45ca12 | B15: BM-O5-01 | C15: O5 | D15: Opdracht verlenen aan uitvoerder | E15: Aan wie verlenen we de opdracht en tegen welke kosten? | F15: Dummy: gunnen van opdracht. | G15: BT-10 | H15: formeel | I15: definitief | J15: Gunnen van opdracht | K15: Raming, aanbestedingsstrategie, juridische afspraken | L15: Gunningsbesluit | M15: Realisatie bewaken | N15: nee | P15: ja | Q15: ja | R15: VS-02 | S15: 2026-10-03 | T15: dummy-generator | U15: 2026-10-03 | V15: dummy-generator | W15: concept | X15: 1 | AA15: DUMMY
A16: 1331e508-d2d5-57a0-b71a-339da74d3b20 | B16: BM-O6-01 | C16: O6 | D16: Oplevering accepteren | E16: Is het opgeleverd conform afspraken en wat zijn de beheerkosten? | F16: Dummy: accepteren van oplevering. | G16: BT-11 | H16: ambtelijk | I16: definitief | J16: Accepteren van oplevering | K16: Technische staat, exploitatiegegevens | L16: Opleverdossier | M16: In gebruik nemen | N16: nee | P16: ja | Q16: ja | R16: VS-02 | S16: 2026-10-03 | T16: dummy-generator | U16: 2026-10-03 | V16: dummy-generator | W16: concept | X16: 1 | AA16: DUMMY
A17: 2e2c89d9-0a51-5230-9d92-c0de821b80a1 | B17: BM-O7-01 | C17: O7 | D17: Exploitatie en prestaties evalueren | E17: Presteert het object zoals bedoeld en wat leren we? | F17: Dummy: evalueren en bijsturen. | G17: BT-12 | H17: ambtelijk | I17: richtinggevend | J17: Evalueren en bijsturen | K17: Verbruik, exploitatie, voortgang, gebruik | L17: Evaluatie en monitoringsrapportage | M17: Terugkoppelen naar portefeuille | N17: nee | O17: PC-07 | P17: ja | Q17: ja | R17: VS-02 | S17: 2026-10-03 | T17: dummy-generator | U17: 2026-10-03 | V17: dummy-generator | W17: concept | X17: 1 | AA17: DUMMY

Sheet besluittype
A1: besluittype_id | B1: code | C1: naam | D1: omschrijving | E1: sort_order | F1: created_at | G1: created_by | H1: updated_at | I1: updated_by | J1: record_status | K1: version_number | L1: valid_from | M1: valid_until | N1: notes_internal
A2: e5d229a1-26b1-58fc-8f15-f48996c7c9ef | B2: BT-01 | C2: verkennend | E2: 1 | F2: 2026-10-02 | G2: startwaardelijst datamodel | H2: 2026-10-02 | I2: startwaardelijst datamodel | J2: concept | K2: 1
A3: a6589a86-6c2d-5d1f-ac92-7157cb398233 | B3: BT-02 | C3: richtinggevend | E3: 2 | F3: 2026-10-02 | G3: startwaardelijst datamodel | H3: 2026-10-02 | I3: startwaardelijst datamodel | J3: concept | K3: 1
A4: a5c66e9a-5ac6-5c1a-84f0-d2f8fa665d89 | B4: BT-03 | C4: kaderstellend | E4: 3 | F4: 2026-10-02 | G4: startwaardelijst datamodel | H4: 2026-10-02 | I4: startwaardelijst datamodel | J4: concept | K4: 1
A5: f11e278c-42f9-5067-a1ad-4946e767a6a9 | B5: BT-04 | C5: prioriterend | E5: 4 | F5: 2026-10-02 | G5: startwaardelijst datamodel | H5: 2026-10-02 | I5: startwaardelijst datamodel | J5: concept | K5: 1
A6: 6e065eab-74fb-50c5-adb0-f173920b38a2 | B6: BT-05 | C6: programmerend | E6: 5 | F6: 2026-10-02 | G6: startwaardelijst datamodel | H6: 2026-10-02 | I6: startwaardelijst datamodel | J6: concept | K6: 1
A7: c1204c95-2f13-529f-bfaa-98af8667dca6 | B7: BT-06 | C7: financieel toetsend | E7: 6 | F7: 2026-10-02 | G7: startwaardelijst datamodel | H7: 2026-10-02 | I7: startwaardelijst datamodel | J7: concept | K7: 1
A8: 13b42bbe-207e-5dba-8de6-67238edf4976 | B8: BT-07 | C8: investeringsbesluit | E8: 7 | F8: 2026-10-02 | G8: startwaardelijst datamodel | H8: 2026-10-02 | I8: startwaardelijst datamodel | J8: concept | K8: 1
